Workbook

Sheet Importtabelle
A1: Studiengang | B1: Fachbereich | C1: Studienanfänger -4 | D1: Studienanfänger -3 | E1: Studienanfänger -2 | F1: Studienanfänger -1 | G1: Immatrikulierte Studierende -4 | H1: Immatrikulierte Studierende -3 | I1: Immatrikulierte Studierende -2 | J1: Immatrikulierte Studierende -1 | K1: Hochschultyp des Vorstudiums der Studienanfänger [PROFIL] | L1: Erfolgsquote der Studierenden | M1: Anzahl der fürs Studium benötigten Fachsemester | N1: Berufserfahrung der Studienanfänger | O1: Alter zum Beginn des Studiums | P1: Herkunft Dozent (Anteil an Lehrveranstaltungsstunden) [Profil] | Q1: In welchen Studiengängen belegen die Studierenden Module?Studiengang? [Profil] | R1: Aus welchem Studiengang kommen die Modulteilnehmer? [Profil] | S1: Durchschnittliche Modulbelegung
A2: Advanced Practice in Healthcare | B2: Gesundheit | C2: 22 | D2: 15 | E2: 17 | F2: 15 | G2: 22 | H2: 35 | I2: 52 | J2: 51 | K2: {="{"&_xlfn.TEXTJOIN("; ",TRUE,Vorstudium!C$1:F$1&": "&Vorstudium!C2:F2)&"}"} -> {DHBW: 7; Hochschule: 6; Universität: 1; Ausland/k.A.: 1} | L2: 0.88888889 | M2: 5.125 | N2: 2.8555556 | O2: 34.866667 | P2: {="{"&_xlfn.TEXTJOIN("; ",TRUE,'Doz-Herkunft'!C$1:J$1&": "&'Doz-Herkunft'!C2:J2)&"}"} -> {DHBW: 978; andere Hochschule: 306; Forschungsinstitut: ; freiberufl./selbst.: 108; Öffentliche Einrichtung: 148; Rechtsanwalt / StB/ Richter: ; Soz. Einrichtung / Verbände: 48; Unternehmen: 16} | Q2: {=_xlfn.LET( _xlpm.keys,Lehrverflechtung!$B$2:$B$30, _xlpm.k,ROW()-1, _xlpm.vals,INDEX(Lehrverflechtung!$C$2:$AE$30,_xlfn.SEQUENCE(29),_xlpm.k), IF(_xlpm.k>29,"","{"&_xlfn.TEXTJOIN("; ",TRUE,_xlpm.keys&": "&_xlpm.vals)&"}") )} -> {Advanced Practice in Healthcare: 280; Intensive Care: ; Digitalisierung in der Sozialen Arbeit: ; Governance Sozialer Arbeit: ; Planung und Koordination in der Sozialen Arbeit: ; Soziale Arbeit in der Migrationsgesellschaft: ; Transkulturelle Traumapädagogik: ; Bauingenieurwesen: ; Elektrotechnik und Informationstechnik: ; Executive Engineering: ; Informatik: ; Integrated Engineering: ; Maschinenbau: ; Wirtschaftsingenieurwesen: ; Accounting, Controlling, Taxation: ; Data Science and Artificial Intelligence: ; Digital Business Management: ; Entrepreneurship: ; Finance: ; General Business Management: ; Marketing: ; Master of Business Administration: ; Media and Data-driven Business: ; Personalmanagement und Wirtschaftspsychologie: ; Rechnungswesen Steuern Wirtschaftsrecht: ; Sales and Negotiation: ; Supply Chain Management, Logistics, Production: ; Wirtschaftsinformatik: ; Fachübergreifende Kompetenzen: 61} | R2: {="{"&_xlfn.TEXTJOIN("; ",TRUE,Lehrverflechtung!C$1:AF$1&": "&Lehrverflechtung!C2:AF2)&"}"} -> {Advanced Practice in Healthcare: 280; Intensive Care: ; Digitalisierung in der Sozialen Arbeit: ; Governance Sozialer Arbeit: 1; Planung und Koordination in der Sozialen Arbeit: ; Soziale Arbeit in der Migrationsgesellschaft: ; Transkulturelle Traumapädagogik: ; Bauingenieurwesen: ; Elektrotechnik und Informationstechnik: ; Executive Engineering: ; Informatik: ; Integrated Engineering: ; Maschinenbau: ; Wirtschaftsingenieurwesen: ; Accounting, Controlling, Taxation: ; Data Science and Artificial Intelligence: ; Digital Business Management: ; Entrepreneurship: ; Finance: ; General Business Management: ; Marketing: ; Master of Business Administration: ; Media and Data-driven Business: ; Personalmanagement und Wirtschaftspsychologie: ; Rechnungswesen Steuern Wirtschaftsrecht: ; Sales and Negotiation: ; Supply Chain Management, Logistics, Production: ; Wirtschaftsinformatik: ; Fachübergreifende Kompetenzen: ; Wissenschaftliche Weiterbildung: 62} | S2: 8.5
A3: Intensive Care | B3: Gesundheit | C3: 0 | D3: 0 | E3: 6 | F3: 13 | G3: 0 | H3: 0 | I3: 6 | J3: 19 | K3: {="{"&_xlfn.TEXTJOIN("; ",TRUE,Vorstudium!C$1:F$1&": "&Vorstudium!C3:F3)&"}"} -> {DHBW: 7; Hochschule: 5; Universität: ; Ausland/k.A.: 1} | N3: 2.2307692 | O3: 28.923077 | P3: {="{"&_xlfn.TEXTJOIN("; ",TRUE,'Doz-Herkunft'!C$1:J$1&": "&'Doz-Herkunft'!C3:J3)&"}"} -> {DHBW: 132; andere Hochschule: 52; Forschungsinstitut: 16; freiberufl./selbst.: 92; Öffentliche Einrichtung: 316; Rechtsanwalt / StB/ Richter: ; Soz. Einrichtung / Verbände: ; Unternehmen: 16} | Q3: {=_xlfn.LET( _xlpm.keys,Lehrverflechtung!$B$2:$B$31, _xlpm.k,ROW()-1, _xlpm.vals,INDEX(Lehrverflechtung!$C$2:$AF$31,_xlfn.SEQUENCE(30),_xlpm.k), IF(_xlpm.k>30,"","{"&_xlfn.TEXTJOIN("; ",TRUE,_xlpm.keys&": "&_xlpm.vals)&"}") )} -> {Advanced Practice in Healthcare: ; Intensive Care: 96; Digitalisierung in der Sozialen Arbeit: ; Governance Sozialer Arbeit: ; Planung und Koordination in der Sozialen Arbeit: ; Soziale Arbeit in der Migrationsgesellschaft: ; Transkulturelle Traumapädagogik: ; Bauingenieurwesen: ; Elektrotechnik und Informationstechnik: ; Executive Engineering: ; Informatik: ; Integrated Engineering: ; Maschinenbau: ; Wirtschaftsingenieurwesen: ; Accounting, Controlling, Taxation: ; Data Science and Artificial Intelligence: ; Digital Business Management: ; Entrepreneurship: ; Finance: ; General Business Management: ; Marketing: ; Master of Business Administration: ; Media and Data-driven Business: ; Personalmanagement und Wirtschaftspsychologie: ; Rechnungswesen Steuern Wirtschaftsrecht: ; Sales and Negotiation: ; Supply Chain Management, Logistics, Production: ; Wirtschaftsinformatik: ; Fachübergreifende Kompetenzen: ; Wissenschaftliche Weiterbildung: } | R3: {="{"&_xlfn.TEXTJOIN("; ",TRUE,Lehrverflechtung!C$1:AF$1&": "&Lehrverflechtung!C3:AF3)&"}"} -> {Advanced Practice in Healthcare: ; Intensive Care: 96; Digitalisierung in der Sozialen Arbeit: ; Governance Sozialer Arbeit: ; Planung und Koordination in der Sozialen Arbeit: ; Soziale Arbeit in der Migrationsgesellschaft: ; Transkulturelle Traumapädagogik: ; Bauingenieurwesen: ; Elektrotechnik und Informationstechnik: ; Executive Engineering: ; Informatik: ; Integrated Engineering: ; Maschinenbau: ; Wirtschaftsingenieurwesen: ; Accounting, Controlling, Taxation: ; Data Science and Artificial Intelligence: ; Digital Business Management: ; Entrepreneurship: ; Finance: ; General Business Management: ; Marketing: ; Master of Business Administration: ; Media and Data-driven Business: ; Personalmanagement und Wirtschaftspsychologie: ; Rechnungswesen Steuern Wirtschaftsrecht: ; Sales and Negotiation: ; Supply Chain Management, Logistics, Production: ; Wirtschaftsinformatik: ; Fachübergreifende Kompetenzen: ; Wissenschaftliche Weiterbildung: 4} | S3: 12.75
A4: Digitalisierung in der Sozialen Arbeit | B4: Sozialwesen | C4: 17 | D4: 3 | E4: 10 | F4: 4 | G4: 22 | H4: 23 | I4: 32 | J4: 26 | K4: {="{"&_xlfn.TEXTJOIN("; ",TRUE,Vorstudium!C$1:F$1&": "&Vorstudium!C4:F4)&"}"} -> {DHBW: 3; Hochschule: 1; Universität: ; Ausland/k.A.: } | L4: 0.92307692 | M4: 5.5 | N4: 3.3333333 | O4: 29 | P4: {="{"&_xlfn.TEXTJOIN("; ",TRUE,'Doz-Herkunft'!C$1:J$1&": "&'Doz-Herkunft'!C4:J4)&"}"} -> {DHBW: 404; andere Hochschule: 162; Forschungsinstitut: ; freiberufl./selbst.: 144; Öffentliche Einrichtung: 80; Rechtsanwalt / StB/ Richter: ; Soz. Einrichtung / Verbände: ; Unternehmen: } | Q4: {=_xlfn.LET( _xlpm.keys,Lehrverflechtung!$B$2:$B$31, _xlpm.k,ROW()-1, _xlpm.vals,INDEX(Lehrverflechtung!$C$2:$AF$31,_xlfn.SEQUENCE(30),_xlpm.k), IF(_xlpm.k>30,"","{"&_xlfn.TEXTJOIN("; ",TRUE,_xlpm.keys&": "&_xlpm.vals)&"}") )} -> {Advanced Practice in Healthcare: ; Intensive Care: ; Digitalisierung in der Sozialen Arbeit: 121; Governance Sozialer Arbeit: 5; Planung und Koordination in der Sozialen Arbeit: 8; Soziale Arbeit in der Migrationsgesellschaft: 2; Transkulturelle Traumapädagogik: 1; Bauingenieurwesen: ; Elektrotechnik und Informationstechnik: ; Executive Engineering: ; Informatik: ; Integrated Engineering: ; Maschinenbau: ; Wirtschaftsingenieurwesen: ; Accounting, Controlling, Taxation: ; Data Science and Artificial Intelligence: ; Digital Business Management: 1; Entrepreneurship: ; Finance: ; General Business Management: ; Marketing: ; Master of Business Administration: ; Media and Data-driven Business: ; Personalmanagement und Wirtschaftspsychologie: ; Rechnungswesen Steuern Wirtschaftsrecht: ; Sales and Negotiation: ; Supply Chain Management, Logistics, Production: ; Wirtschaftsinformatik: 5; Fachübergreifende Kompetenzen: ; Wissenschaftliche Weiterbildung: } | R4: {="{"&_xlfn.TEXTJOIN("; ",TRUE,Lehrverflechtung!C$1:AF$1&": "&Lehrverflechtung!C4:AF4)&"}"} -> {Advanced Practice in Healthcare: ; Intensive Care: ; Digitalisierung in der Sozialen Arbeit: 121; Governance Sozialer Arbeit: 4; Planung und Koordination in der Sozialen Arbeit: 5; Soziale Arbeit in der Migrationsgesellschaft: 1; Transkulturelle Traumapädagogik: 1; Bauingenieurwesen: ; Elektrotechnik und Informationstechnik: ; Executive Engineering: ; Informatik: ; Integrated Engineering: ; Maschinenbau: ; Wirtschaftsingenieurwesen: ; Accounting, Controlling, Taxation: ; Data Science and Artificial Intelligence: ; Digital Business Management: ; Entrepreneurship: ; Finance: ; General Business Management: ; Marketing: ; Master of Business Administration: ; Media and Data-driven Business: ; Personalmanagement und Wirtschaftspsychologie: ; Rechnungswesen Steuern Wirtschaftsrecht: ; Sales and Negotiation: ; Supply Chain Management, Logistics, Production: ; Wirtschaftsinformatik: ; Fachübergreifende Kompetenzen: ; Wissenschaftliche Weiterbildung: 17} | S4: 6.6
A5: Governance Sozialer Arbeit | B5: Sozialwesen | C5: 10 | D5: 14 | E5: 5 | F5: 5 | G5: 55 | H5: 51 | I5: 45 | J5: 40 | K5: {="{"&_xlfn.TEXTJOIN("; ",TRUE,Vorstudium!C$1:F$1&": "&Vorstudium!C5:F5)&"}"} -> {DHBW: 3; Hochschule: 1; Universität: 1; Ausland/k.A.: } | L5: 0.9 | M5: 5.1369863 | N5: 2 | O5: 26.8 | P5: {="{"&_xlfn.TEXTJOIN("; ",TRUE,'Doz-Herkunft'!C$1:J$1&": "&'Doz-Herkunft'!C5:J5)&"}"} -> {DHBW: 638; andere Hochschule: 36; Forschungsinstitut: ; freiberufl./selbst.: 378; Öffentliche Einrichtung: ; Rechtsanwalt / StB/ Richter: 16; Soz. Einrichtung / Verbände: 48; Unternehmen: 64} | Q5: {=_xlfn.LET( _xlpm.keys,Lehrverflechtung!$B$2:$B$31, _xlpm.k,ROW()-1, _xlpm.vals,INDEX(Lehrverflechtung!$C$2:$AF$31,_xlfn.SEQUENCE(30),_xlpm.k), IF(_xlpm.k>30,"","{"&_xlfn.TEXTJOIN("; ",TRUE,_xlpm.keys&": "&_xlpm.vals)&"}") )} -> {Advanced Practice in Healthcare: 1; Intensive Care: ; Digitalisierung in der Sozialen Arbeit: 4; Governance Sozialer Arbeit: 101; Planung und Koordination in der Sozialen Arbeit: 9; Soziale Arbeit in der Migrationsgesellschaft: 5; Transkulturelle Traumapädagogik: 7; Bauingenieurwesen: ; Elektrotechnik und Informationstechnik: ; Executive Engineering: ; Informatik: ; Integrated Engineering: ; Maschinenbau: ; Wirtschaftsingenieurwesen: ; Accounting, Controlling, Taxation: ; Data Science and Artificial Intelligence: ; Digital Business Management: ; Entrepreneurship: ; Finance: ; General Business Management: ; Marketing: ; Master of Business Administration: ; Media and Data-driven Business: ; Personalmanagement und Wirtschaftspsychologie: ; Rechnungswesen Steuern Wirtschaftsrecht: ; Sales and Negotiation: ; Supply Chain Management, Logistics, Production: ; Wirtschaftsinformatik: ; Fachübergreifende Kompetenzen: ; Wissenschaftliche Weiterbildung: } | R5: {="{"&_xlfn.TEXTJOIN("; ",TRUE,Lehrverflechtung!C$1:AF$1&": "&Lehrverflechtung!C5:AF5)&"}"} -> {Advanced Practice in Healthcare: ; Intensive Care: ; Digitalisierung in der Sozialen Arbeit: 5; Governance Sozialer Arbeit: 101; Planung und Koordination in der Sozialen Arbeit: 18; Soziale Arbeit in der Migrationsgesellschaft: 1; Transkulturelle Traumapädagogik: 1; Bauingenieurwesen: ; Elektrotechnik und Informationstechnik: ; Executive Engineering: ; Informatik: ; Integrated Engineering: ; Maschinenbau: ; Wirtschaftsingenieurwesen: ; Accounting, Controlling, Taxation: ; Data Science and Artificial Intelligence: ; Digital Business Management: ; Entrepreneurship: ; Finance: ; General Business Management: ; Marketing: ; Master of Business Administration: ; Media and Data-driven Business: ; Personalmanagement und Wirtschaftspsychologie: ; Rechnungswesen Steuern Wirtschaftsrecht: ; Sales and Negotiation: ; Supply Chain Management, Logistics, Production: ; Wirtschaftsinformatik: ; Fachübergreifende Kompetenzen: ; Wissenschaftliche Weiterbildung: } | S5: 6.4
A6: Planung und Koordination in der Sozialen Arbeit | B6: Sozialwesen | C6: 6 | D6: 10 | E6: 7 | F6: 3 | G6: 19 | H6: 23 | I6: 27 | J6: 19 | K6: {="{"&_xlfn.TEXTJOIN("; ",TRUE,Vorstudium!C$1:F$1&": "&Vorstudium!C6:F6)&"}"} -> {DHBW: 1; Hochschule: ; Universität: 1; Ausland/k.A.: 1} | L6: 0.875 | M6: 5.1785714 | N6: 1.6111111 | O6: 24.666667 | P6: {="{"&_xlfn.TEXTJOIN("; ",TRUE,'Doz-Herkunft'!C$1:J$1&": "&'Doz-Herkunft'!C6:J6)&"}"} -> {DHBW: 360; andere Hochschule: ; Forschungsinstitut: 32; freiberufl./selbst.: 80; Öffentliche Einrichtung: 63; Rechtsanwalt / StB/ Richter: ; Soz. Einrichtung / Verbände: ; Unternehmen: 32} | Q6: {=_xlfn.LET( _xlpm.keys,Lehrverflechtung!$B$2:$B$31, _xlpm.k,ROW()-1, _xlpm.vals,INDEX(Lehrverflechtung!$C$2:$AF$31,_xlfn.SEQUENCE(30),_xlpm.k), IF(_xlpm.k>30,"","{"&_xlfn.TEXTJOIN("; ",TRUE,_xlpm.keys&": "&_xlpm.vals)&"}") )} -> {Advanced Practice in Healthcare: ; Intensive Care: ; Digitalisierung in der Sozialen Arbeit: 5; Governance Sozialer Arbeit: 18; Planung und Koordination in der Sozialen Arbeit: 88; Soziale Arbeit in der Migrationsgesellschaft: 9; Transkulturelle Traumapädagogik: 10; Bauingenieurwesen: ; Elektrotechnik und Informationstechnik: ; Executive Engineering: ; Informatik: ; Integrated Engineering: ; Maschinenbau: ; Wirtschaftsingenieurwesen: ; Accounting, Controlling, Taxation: ; Data Science and Artificial Intelligence: ; Digital Business Management: ; Entrepreneurship: ; Finance: ; General Business Management: ; Marketing: ; Master of Business Administration: ; Media and Data-driven Business: ; Personalmanagement und Wirtschaftspsychologie: ; Rechnungswesen Steuern Wirtschaftsrecht: ; Sales and Negotiation: ; Supply Chain Management, Logistics, Production: ; Wirtschaftsinformatik: ; Fachübergreifende Kompetenzen: ; Wissenschaftliche Weiterbildung: } | R6: {="{"&_xlfn.TEXTJOIN("; ",TRUE,Lehrverflechtung!C$1:AF$1&": "&Lehrverflechtung!C6:AF6)&"}"} -> {Advanced Practice in Healthcare: ; Intensive Care: ; Digitalisierung in der Sozialen Arbeit: 8; Governance Sozialer Arbeit: 9; Planung und Koordination in der Sozialen Arbeit: 88; Soziale Arbeit in der Migrationsgesellschaft: 2; Transkulturelle Traumapädagogik: ; Bauingenieurwesen: ; Elektrotechnik und Informationstechnik: ; Executive Engineering: ; Informatik: ; Integrated Engineering: ; Maschinenbau: ; Wirtschaftsingenieurwesen: ; Accounting, Controlling, Taxation: ; Data Science and Artificial Intelligence: ; Digital Business Management: ; Entrepreneurship: ; Finance: ; General Business Management: ; Marketing: ; Master of Business Administration: ; Media and Data-driven Business: ; Personalmanagement und Wirtschaftspsychologie: ; Rechnungswesen Steuern Wirtschaftsrecht: ; Sales and Negotiation: ; Supply Chain Management, Logistics, Production: ; Wirtschaftsinformatik: ; Fachübergreifende Kompetenzen: ; Wissenschaftliche Weiterbildung: 13} | S6: 6.5
A7: Soziale Arbeit in der Migrationsgesellschaft | B7: Sozialwesen | C7: 8 | D7: 4 | E7: 6 | F7: 6 | G7: 31 | H7: 30 | I7: 25 | J7: 29 | K7: {="{"&_xlfn.TEXTJOIN("; ",TRUE,Vorstudium!C$1:F$1&": "&Vorstudium!C7:F7)&"}"} -> {DHBW: 1; Hochschule: 1; Universität: 4; Ausland/k.A.: } | L7: 0.9 | M7: 5.7407407 | N7: 1.6527778 | O7: 27 | P7: {="{"&_xlfn.TEXTJOIN("; ",TRUE,'Doz-Herkunft'!C$1:J$1&": "&'Doz-Herkunft'!C7:J7)&"}"} -> {DHBW: 336; andere Hochschule: 64; Forschungsinstitut: ; freiberufl./selbst.: 32; Öffentliche Einrichtung: 16; Rechtsanwalt / StB/ Richter: 80; Soz. Einrichtung / Verbände: 32; Unternehmen: 48} | Q7: {=_xlfn.LET( _xlpm.keys,Lehrverflechtung!$B$2:$B$31, _xlpm.k,ROW()-1, _xlpm.vals,INDEX(Lehrverflechtung!$C$2:$AF$31,_xlfn.SEQUENCE(30),_xlpm.k), IF(_xlpm.k>30,"","{"&_xlfn.TEXTJOIN("; ",TRUE,_xlpm.keys&": "&_xlpm.vals)&"}") )} -> {Advanced Practice in Healthcare: ; Intensive Care: ; Digitalisierung in der Sozialen Arbeit: 1; Governance Sozialer Arbeit: 1; Planung und Koordination in der Sozialen Arbeit: 2; Soziale Arbeit in der Migrationsgesellschaft: 80; Transkulturelle Traumapädagogik: 16; Bauingenieurwesen: ; Elektrotechnik und Informationstechnik: ; Executive Engineering: ; Informatik: ; Integrated Engineering: ; Maschinenbau: ; Wirtschaftsingenieurwesen: ; Accounting, Controlling, Taxation: ; Data Science and Artificial Intelligence: ; Digital Business Management: ; Entrepreneurship: ; Finance: ; General Business Management: ; Marketing: ; Master of Business Administration: ; Media and Data-driven Business: ; Personalmanagement und Wirtschaftspsychologie: ; Rechnungswesen Steuern Wirtschaftsrecht: ; Sales and Negotiation: ; Supply Chain Management, Logistics, Production: ; Wirtschaftsinformatik: ; Fachübergreifende Kompetenzen: ; Wissenschaftliche Weiterbildung: } | R7: {="{"&_xlfn.TEXTJOIN("; ",TRUE,Lehrverflechtung!C$1:AF$1&": "&Lehrverflechtung!C7:AF7)&"}"} -> {Advanced Practice in Healthcare: ; Intensive Care: ; Digitalisierung in der Sozialen Arbeit: 2; Governance Sozialer Arbeit: 5; Planung und Koordination in der Sozialen Arbeit: 9; Soziale Arbeit in der Migrationsgesellschaft: 80; Transkulturelle Traumapädagogik: 4; Bauingenieurwesen: ; Elektrotechnik und Informationstechnik: ; Executive Engineering: ; Informatik: ; Integrated Engineering: ; Maschinenbau: ; Wirtschaftsingenieurwesen: ; Accounting, Controlling, Taxation: ; Data Science and Artificial Intelligence: ; Digital Business Management: ; Entrepreneurship: ; Finance: ; General Business Management: ; Marketing: ; Master of Business Administration: ; Media and Data-driven Business: ; Personalmanagement und Wirtschaftspsychologie: ; Rechnungswesen Steuern Wirtschaftsrecht: ; Sales and Negotiation: ; Supply Chain Management, Logistics, Production: ; Wirtschaftsinformatik: ; Fachübergreifende Kompetenzen: ; Wissenschaftliche Weiterbildung: 36} | S7: 5.5
A8: Transkulturelle Traumapädagogik | B8: Sozialwesen | C8: 0 | D8: 0 | E8: 4 | F8: 10 | G8: 0 | H8: 0 | I8: 4 | J8: 14 | K8: {="{"&_xlfn.TEXTJOIN("; ",TRUE,Vorstudium!C$1:F$1&": "&Vorstudium!C8:F8)&"}"} -> {DHBW: 6; Hochschule: 2; Universität: 2; Ausland/k.A.: } | N8: 2.7222222 | O8: 26.9 | P8: {="{"&_xlfn.TEXTJOIN("; ",TRUE,'Doz-Herkunft'!C$1:J$1&": "&'Doz-Herkunft'!C8:J8)&"}"} -> {DHBW: 224; andere Hochschule: 80; Forschungsinstitut: 56; freiberufl./selbst.: 86; Öffentliche Einrichtung: ; Rechtsanwalt / StB/ Richter: ; Soz. Einrichtung / Verbände: 124; Unternehmen: } | Q8: {=_xlfn.LET( _xlpm.keys,Lehrverflechtung!$B$2:$B$31, _xlpm.k,ROW()-1, _xlpm.vals,INDEX(Lehrverflechtung!$C$2:$AF$31,_xlfn.SEQUENCE(30),_xlpm.k), IF(_xlpm.k>30,"","{"&_xlfn.TEXTJOIN("; ",TRUE,_xlpm.keys&": "&_xlpm.vals)&"}") )} -> {Advanced Practice in Healthcare: ; Intensive Care: ; Digitalisierung in der Sozialen Arbeit: 1; Governance Sozialer Arbeit: 1; Planung und Koordination in der Sozialen Arbeit: ; Soziale Arbeit in der Migrationsgesellschaft: 4; Transkulturelle Traumapädagogik: 94; Bauingenieurwesen: ; Elektrotechnik und Informationstechnik: ; Executive Engineering: ; Informatik: ; Integrated Engineering: ; Maschinenbau: ; Wirtschaftsingenieurwesen: ; Accounting, Controlling, Taxation: ; Data Science and Artificial Intelligence: ; Digital Business Management: ; Entrepreneurship: ; Finance: ; General Business Management: ; Marketing: ; Master of Business Administration: ; Media and Data-driven Business: ; Personalmanagement und Wirtschaftspsychologie: ; Rechnungswesen Steuern Wirtschaftsrecht: ; Sales and Negotiation: ; Supply Chain Management, Logistics, Production: ; Wirtschaftsinformatik: ; Fachübergreifende Kompetenzen: ; Wissenschaftliche Weiterbildung: } | R8: {="{"&_xlfn.TEXTJOIN("; ",TRUE,Lehrverflechtung!C$1:AF$1&": "&Lehrverflechtung!C8:AF8)&"}"} -> {Advanced Practice in Healthcare: ; Intensive Care: ; Digitalisierung in der Sozialen Arbeit: 1; Governance Sozialer Arbeit: 7; Planung und Koordination in der Sozialen Arbeit: 10; Soziale Arbeit in der Migrationsgesellschaft: 16; Transkulturelle Traumapädagogik: 94; Bauingenieurwesen: ; Elektrotechnik und Informationstechnik: ; Executive Engineering: ; Informatik: ; Integrated Engineering: ; Maschinenbau: ; Wirtschaftsingenieurwesen: ; Accounting, Controlling, Taxation: ; Data Science and Artificial Intelligence: ; Digital Business Management: ; Entrepreneurship: ; Finance: ; General Business Management: ; Marketing: ; Master of Business Administration: ; Media and Data-driven Business: ; Personalmanagement und Wirtschaftspsychologie: ; Rechnungswesen Steuern Wirtschaftsrecht: ; Sales and Negotiation: ; Supply Chain Management, Logistics, Production: ; Wirtschaftsinformatik: ; Fachübergreifende Kompetenzen: ; Wissenschaftliche Weiterbildung: 41} | S8: 9.8571429
A9: Bauingenieurwesen | B9: Technik | C9: 5 | D9: 14 | E9: 16 | F9: 15 | G9: 6 | H9: 19 | I9: 35 | J9: 47 | K9: {="{"&_xlfn.TEXTJOIN("; ",TRUE,Vorstudium!C$1:F$1&": "&Vorstudium!C9:F9)&"}"} -> {DHBW: 10; Hochschule: 5; Universität: ; Ausland/k.A.: } | L9: 1 | M9: 5.3333333 | N9: 2.2388889 | O9: 27 | P9: {="{"&_xlfn.TEXTJOIN("; ",TRUE,'Doz-Herkunft'!C$1:J$1&": "&'Doz-Herkunft'!C9:J9)&"}"} -> {DHBW: 516; andere Hochschule: 16; Forschungsinstitut: 32; freiberufl./selbst.: 96; Öffentliche Einrichtung: 136; Rechtsanwalt / StB/ Richter: ; Soz. Einrichtung / Verbände: ; Unternehmen: 428} | Q9: {=_xlfn.LET( _xlpm.keys,Lehrverflechtung!$B$2:$B$31, _xlpm.k,ROW()-1, _xlpm.vals,INDEX(Lehrverflechtung!$C$2:$AF$31,_xlfn.SEQUENCE(30),_xlpm.k), IF(_xlpm.k>30,"","{"&_xlfn.TEXTJOIN("; ",TRUE,_xlpm.keys&": "&_xlpm.vals)&"}") )} -> {Advanced Practice in Healthcare: ; Intensive Care: ; Digitalisierung in der Sozialen Arbeit: ; Governance Sozialer Arbeit: ; Planung und Koordination in der Sozialen Arbeit: ; Soziale Arbeit in der Migrationsgesellschaft: ; Transkulturelle Traumapädagogik: ; Bauingenieurwesen: 205; Elektrotechnik und Informationstechnik: 1; Executive Engineering: ; Informatik: ; Integrated Engineering: 1; Maschinenbau: 2; Wirtschaftsingenieurwesen: 30; Accounting, Controlling, Taxation: ; Data Science and Artificial Intelligence: ; Digital Business Management: ; Entrepreneurship: ; Finance: ; General Business Management: 1; Marketing: ; Master of Business Administration: 1; Media and Data-driven Business: ; Personalmanagement und Wirtschaftspsychologie: 2; Rechnungswesen Steuern Wirtschaftsrecht: ; Sales and Negotiation: ; Supply Chain Management, Logistics, Production: ; Wirtschaftsinformatik: ; Fachübergreifende Kompetenzen: 48; Wissenschaftliche Weiterbildung: } | R9: {="{"&_xlfn.TEXTJOIN("; ",TRUE,Lehrverflechtung!C$1:AF$1&": "&Lehrverflechtung!C9:AF9)&"}"} -> {Advanced Practice in Healthcare: ; Intensive Care: ; Digitalisierung in der Sozialen Arbeit: ; Governance Sozialer Arbeit: ; Planung und Koordination in der Sozialen Arbeit: ; Soziale Arbeit in der Migrationsgesellschaft: ; Transkulturelle Traumapädagogik: ; Bauingenieurwesen: 205; Elektrotechnik und Informationstechnik: 1; Executive Engineering: ; Informatik: 1; Integrated Engineering: 4; Maschinenbau: ; Wirtschaftsingenieurwesen: 39; Accounting, Controlling, Taxation: ; Data Science and Artificial Intelligence: ; Digital Business Management: ; Entrepreneurship: ; Finance: ; General Business Management: ; Marketing: ; Master of Business Administration: ; Media and Data-driven Business: ; Personalmanagement und Wirtschaftspsychologie: ; Rechnungswesen Steuern Wirtschaftsrecht: ; Sales and Negotiation: ; Supply Chain Management, Logistics, Production: ; Wirtschaftsinformatik: ; Fachübergreifende Kompetenzen: ; Wissenschaftliche Weiterbildung: 26} | S9: 13.428571
A10: Elektrotechnik und Informationstechnik | B10: Technik | C10: 11 | D10: 21 | E10: 18 | F10: 24 | G10: 44 | H10: 51 | I10: 54 | J10: 64 | K10: {="{"&_xlfn.TEXTJOIN("; ",TRUE,Vorstudium!C$1:F$1&": "&Vorstudium!C10:F10)&"}"} -> {DHBW: 18; Hochschule: 6; Universität: ; Ausland/k.A.: } | L10: 0.93670886 | M10: 5.6216216 | N10: 2.2083333 | O10: 25.208333 | P10: {="{"&_xlfn.TEXTJOIN("; ",TRUE,'Doz-Herkunft'!C$1:J$1&": "&'Doz-Herkunft'!C10:J10)&"}"} -> {DHBW: 1158; andere Hochschule: 72; Forschungsinstitut: 32; freiberufl./selbst.: 60; Öffentliche Einrichtung: ; Rechtsanwalt / StB/ Richter: ; Soz. Einrichtung / Verbände: ; Unternehmen: 26} | Q10: {=_xlfn.LET( _xlpm.keys,Lehrverflechtung!$B$2:$B$31, _xlpm.k,ROW()-1, _xlpm.vals,INDEX(Lehrverflechtung!$C$2:$AF$31,_xlfn.SEQUENCE(30),_xlpm.k), IF(_xlpm.k>30,"","{"&_xlfn.TEXTJOIN("; ",TRUE,_xlpm.keys&": "&_xlpm.vals)&"}") )} -> {Advanced Practice in Healthcare: ; Intensive Care: ; Digitalisierung in der Sozialen Arbeit: ; Governance Sozialer Arbeit: ; Planung und Koordination in der Sozialen Arbeit: ; Soziale Arbeit in der Migrationsgesellschaft: ; Transkulturelle Traumapädagogik: ; Bauingenieurwesen: 1; Elektrotechnik und Informationstechnik: 167; Executive Engineering: ; Informatik: 56; Integrated Engineering: 31; Maschinenbau: 38; Wirtschaftsingenieurwesen: 33; Accounting, Controlling, Taxation: ; Data Science and Artificial Intelligence: 1; Digital Business Management: ; Entrepreneurship: ; Finance: ; General Business Management: ; Marketing: ; Master of Business Administration: ; Media and Data-driven Business: 1; Personalmanagement und Wirtschaftspsychologie: 1; Rechnungswesen Steuern Wirtschaftsrecht: ; Sales and Negotiation: 1; Supply Chain Management, Logistics, Production: ; Wirtschaftsinformatik: ; Fachübergreifende Kompetenzen: 68; Wissenschaftliche Weiterbildung: } | R10: {="{"&_xlfn.TEXTJOIN("; ",TRUE,Lehrverflechtung!C$1:AF$1&": "&Lehrverflechtung!C10:AF10)&"}"} -> {Advanced Practice in Healthcare: ; Intensive Care: ; Digitalisierung in der Sozialen Arbeit: ; Governance Sozialer Arbeit: ; Planung und Koordination in der Sozialen Arbeit: ; Soziale Arbeit in der Migrationsgesellschaft: ; Transkulturelle Traumapädagogik: ; Bauingenieurwesen: 1; Elektrotechnik und Informationstechnik: 167; Executive Engineering: ; Informatik: 2; Integrated Engineering: 36; Maschinenbau: 5; Wirtschaftsingenieurwesen: 19; Accounting, Controlling, Taxation: ; Data Science and Artificial Intelligence: ; Digital Business Management: ; Entrepreneurship: ; Finance: 1; General Business Management: 1; Marketing: ; Master of Business Administration: ; Media and Data-driven Business: ; Personalmanagement und Wirtschaftspsychologie: ; Rechnungswesen Steuern Wirtschaftsrecht: ; Sales and Negotiation: ; Supply Chain Management, Logistics, Production: ; Wirtschaftsinformatik: ; Fachübergreifende Kompetenzen: ; Wissenschaftliche Weiterbildung: 21} | S10: 13
A11: Executive Engineering | B11: Technik | C11: 0 | D11: 5 | E11: 9 | F11: 6 | G11: 0 | H11: 4 | I11: 13 | J11: 18 | K11: {="{"&_xlfn.TEXTJOIN("; ",TRUE,Vorstudium!C$1:F$1&": "&Vorstudium!C11:F11)&"}"} -> {DHBW: 6; Hochschule: ; Universität: ; Ausland/k.A.: } | L11: 0.5 | M11: 5 | N11: 2.9305556 | O11: 25.333333 | P11: {="{"&_xlfn.TEXTJOIN("; ",TRUE,'Doz-Herkunft'!C$1:J$1&": "&'Doz-Herkunft'!C11:J11)&"}"} -> {DHBW: 396; andere Hochschule: 50; Forschungsinstitut: 56; freiberufl./selbst.: 70; Öffentliche Einrichtung: 2; Rechtsanwalt / StB/ Richter: ; Soz. Einrichtung / Verbände: 8; Unternehmen: 114} | Q11: {=_xlfn.LET( _xlpm.keys,Lehrverflechtung!$B$2:$B$31, _xlpm.k,ROW()-1, _xlpm.vals,INDEX(Lehrverflechtung!$C$2:$AF$31,_xlfn.SEQUENCE(30),_xlpm.k), IF(_xlpm.k>30,"","{"&_xlfn.TEXTJOIN("; ",TRUE,_xlpm.keys&": "&_xlpm.vals)&"}") )} -> {Advanced Practice in Healthcare: ; Intensive Care: ; Digitalisierung in der Sozialen Arbeit: ; Governance Sozialer Arbeit: ; Planung und Koordination in der Sozialen Arbeit: ; Soziale Arbeit in der Migrationsgesellschaft: ; Transkulturelle Traumapädagogik: ; Bauingenieurwesen: ; Elektrotechnik und Informationstechnik: ; Executive Engineering: 105; Informatik: 2; Integrated Engineering: ; Maschinenbau: 3; Wirtschaftsingenieurwesen: 21; Accounting, Controlling, Taxation: ; Data Science and Artificial Intelligence: ; Digital Business Management: ; Entrepreneurship: 3; Finance: ; General Business Management: ; Marketing: ; Master of Business Administration: ; Media and Data-driven Business: 1; Personalmanagement und Wirtschaftspsychologie: 2; Rechnungswesen Steuern Wirtschaftsrecht: ; Sales and Negotiation: ; Supply Chain Management, Logistics, Production: ; Wirtschaftsinformatik: ; Fachübergreifende Kompetenzen: 42; Wissenschaftliche Weiterbildung: } | R11: {="{"&_xlfn.TEXTJOIN("; ",TRUE,Lehrverflechtung!C$1:AF$1&": "&Lehrverflechtung!C11:AF11)&"}"} -> {Advanced Practice in Healthcare: ; Intensive Care: ; Digitalisierung in der Sozialen Arbeit: ; Governance Sozialer Arbeit: ; Planung und Koordination in der Sozialen Arbeit: ; Soziale Arbeit in der Migrationsgesellschaft: ; Transkulturelle Traumapädagogik: ; Bauingenieurwesen: ; Elektrotechnik und Informationstechnik: ; Executive Engineering: 105; Informatik: ; Integrated Engineering: ; Maschinenbau: ; Wirtschaftsingenieurwesen: ; Accounting, Controlling, Taxation: ; Data Science and Artificial Intelligence: ; Digital Business Management: ; Entrepreneurship: ; Finance: ; General Business Management: ; Marketing: ; Master of Business Administration: ; Media and Data-driven Business: ; Personalmanagement und Wirtschaftspsychologie: ; Rechnungswesen Steuern Wirtschaftsrecht: ; Sales and Negotiation: ; Supply Chain Management, Logistics, Production: ; Wirtschaftsinformatik: ; Fachübergreifende Kompetenzen: ; Wissenschaftliche Weiterbildung: } | S11: 6.75
A12: Informatik | B12: Technik | C12: 27 | D12: 39 | E12: 36 | F12: 39 | G12: 100 | H12: 115 | I12: 118 | J12: 124 | K12: {="{"&_xlfn.TEXTJOIN("; ",TRUE,Vorstudium!C$1:F$1&": "&Vorstudium!C12:F12)&"}"} -> {DHBW: 30; Hochschule: 5; Universität: 2; Ausland/k.A.: 2} | L12: 0.85135135 | M12: 6.4277778 | N12: 2.3653846 | O12: 25.820513 | P12: {="{"&_xlfn.TEXTJOIN("; ",TRUE,'Doz-Herkunft'!C$1:J$1&": "&'Doz-Herkunft'!C12:J12)&"}"} -> {DHBW: 1560; andere Hochschule: 16; Forschungsinstitut: 128; freiberufl./selbst.: 96; Öffentliche Einrichtung: ; Rechtsanwalt / StB/ Richter: ; Soz. Einrichtung / Verbände: ; Unternehmen: 24} | Q12: {=_xlfn.LET( _xlpm.keys,Lehrverflechtung!$B$2:$B$31, _xlpm.k,ROW()-1, _xlpm.vals,INDEX(Lehrverflechtung!$C$2:$AF$31,_xlfn.SEQUENCE(30),_xlpm.k), IF(_xlpm.k>30,"","{"&_xlfn.TEXTJOIN("; ",TRUE,_xlpm.keys&": "&_xlpm.vals)&"}") )} -> {Advanced Practice in Healthcare: ; Intensive Care: ; Digitalisierung in der Sozialen Arbeit: ; Governance Sozialer Arbeit: ; Planung und Koordination in der Sozialen Arbeit: ; Soziale Arbeit in der Migrationsgesellschaft: ; Transkulturelle Traumapädagogik: ; Bauingenieurwesen: 1; Elektrotechnik und Informationstechnik: 2; Executive Engineering: ; Informatik: 369; Integrated Engineering: 12; Maschinenbau: 1; Wirtschaftsingenieurwesen: 42; Accounting, Controlling, Taxation: ; Data Science and Artificial Intelligence: 11; Digital Business Management: ; Entrepreneurship: ; Finance: ; General Business Management: ; Marketing: ; Master of Business Administration: ; Media and Data-driven Business: 28; Personalmanagement und Wirtschaftspsychologie: 3; Rechnungswesen Steuern Wirtschaftsrecht: ; Sales and Negotiation: 1; Supply Chain Management, Logistics, Production: ; Wirtschaftsinformatik: 136; Fachübergreifende Kompetenzen: 131; Wissenschaftliche Weiterbildung: } | R12: {="{"&_xlfn.TEXTJOIN("; ",TRUE,Lehrverflechtung!C$1:AF$1&": "&Lehrverflechtung!C12:AF12)&"}"} -> {Advanced Practice in Healthcare: ; Intensive Care: ; Digitalisierung in der Sozialen Arbeit: ; Governance Sozialer Arbeit: ; Planung und Koordination in der Sozialen Arbeit: ; Soziale Arbeit in der Migrationsgesellschaft: ; Transkulturelle Traumapädagogik: ; Bauingenieurwesen: ; Elektrotechnik und Informationstechnik: 56; Executive Engineering: 2; Informatik: 369; Integrated Engineering: 23; Maschinenbau: 13; Wirtschaftsingenieurwesen: 28; Accounting, Controlling, Taxation: ; Data Science and Artificial Intelligence: 5; Digital Business Management: 2; Entrepreneurship: ; Finance: ; General Business Management: ; Marketing: ; Master of Business Administration: ; Media and Data-driven Business: 2; Personalmanagement und Wirtschaftspsychologie: ; Rechnungswesen Steuern Wirtschaftsrecht: ; Sales and Negotiation: ; Supply Chain Management, Logistics, Production: ; Wirtschaftsinformatik: 89; Fachübergreifende Kompetenzen: ; Wissenschaftliche Weiterbildung: 61} | S12: 16.666667
A13: Integrated Engineering | B13: Technik | C13: 20 | D13: 37 | E13: 31 | F13: 22 | G13: 116 | H13: 120 | I13: 117 | J13: 115 | K13: {="{"&_xlfn.TEXTJOIN("; ",TRUE,Vorstudium!C$1:F$1&": "&Vorstudium!C13:F13)&"}"} -> {DHBW: 18; Hochschule: 4; Universität: ; Ausland/k.A.: } | L13: 0.97927461 | M13: 6.2645503 | N13: 2.5606061 | O13: 26.272727 | P13: {="{"&_xlfn.TEXTJOIN("; ",TRUE,'Doz-Herkunft'!C$1:J$1&": "&'Doz-Herkunft'!C13:J13)&"}"} -> {DHBW: 1032; andere Hochschule: 72; Forschungsinstitut: 64; freiberufl./selbst.: 160; Öffentliche Einrichtung: ; Rechtsanwalt / StB/ Richter: ; Soz. Einrichtung / Verbände: ; Unternehmen: } | Q13: {=_xlfn.LET( _xlpm.keys,Lehrverflechtung!$B$2:$B$31, _xlpm.k,ROW()-1, _xlpm.vals,INDEX(Lehrverflechtung!$C$2:$AF$31,_xlfn.SEQUENCE(30),_xlpm.k), IF(_xlpm.k>30,"","{"&_xlfn.TEXTJOIN("; ",TRUE,_xlpm.keys&": "&_xlpm.vals)&"}") )} -> {Advanced Practice in Healthcare: ; Intensive Care: ; Digitalisierung in der Sozialen Arbeit: ; Governance Sozialer Arbeit: ; Planung und Koordination in der Sozialen Arbeit: ; Soziale Arbeit in der Migrationsgesellschaft: ; Transkulturelle Traumapädagogik: ; Bauingenieurwesen: 4; Elektrotechnik und Informationstechnik: 36; Executive Engineering: ; Informatik: 23; Integrated Engineering: 103; Maschinenbau: 86; Wirtschaftsingenieurwesen: 160; Accounting, Controlling, Taxation: 1; Data Science and Artificial Intelligence: ; Digital Business Management: 7; Entrepreneurship: ; Finance: ; General Business Management: 3; Marketing: ; Master of Business Administration: 2; Media and Data-driven Business: 4; Personalmanagement und Wirtschaftspsychologie: 1; Rechnungswesen Steuern Wirtschaftsrecht: ; Sales and Negotiation: 3; Supply Chain Management, Logistics, Production: ; Wirtschaftsinformatik: 18; Fachübergreifende Kompetenzen: 80; Wissenschaftliche Weiterbildung: } | R13: {="{"&_xlfn.TEXTJOIN("; ",TRUE,Lehrverflechtung!C$1:AF$1&": "&Lehrverflechtung!C13:AF13)&"}"} -> {Advanced Practice in Healthcare: ; Intensive Care: ; Digitalisierung in der Sozialen Arbeit: ; Governance Sozialer Arbeit: ; Planung und Koordination in der Sozialen Arbeit: ; Soziale Arbeit in der Migrationsgesellschaft: ; Transkulturelle Traumapädagogik: ; Bauingenieurwesen: 1; Elektrotechnik und Informationstechnik: 31; Executive Engineering: ; Informatik: 12; Integrated Engineering: 103; Maschinenbau: 3; Wirtschaftsingenieurwesen: 29; Accounting, Controlling, Taxation: ; Data Science and Artificial Intelligence: ; Digital Business Management: ; Entrepreneurship: ; Finance: ; General Business Management: 1; Marketing: ; Master of Business Administration: ; Media and Data-driven Business: ; Personalmanagement und Wirtschaftspsychologie: ; Rechnungswesen Steuern Wirtschaftsrecht: ; Sales and Negotiation: ; Supply Chain Management, Logistics, Production: ; Wirtschaftsinformatik: 3; Fachübergreifende Kompetenzen: ; Wissenschaftliche Weiterbildung: 41} | S13: 11.4
A14: Maschinenbau | B14: Technik | C14: 27 | D14: 22 | E14: 25 | F14: 17 | G14: 113 | H14: 106 | I14: 89 | J14: 78 | K14: {="{"&_xlfn.TEXTJOIN("; ",TRUE,Vorstudium!C$1:F$1&": "&Vorstudium!C14:F14)&"}"} -> {DHBW: 14; Hochschule: 3; Universität: ; Ausland/k.A.: } | L14: 0.96686747 | M14: 5.8906752 | N14: 2.2647059 | O14: 25.117647 | P14: {="{"&_xlfn.TEXTJOIN("; ",TRUE,'Doz-Herkunft'!C$1:J$1&": "&'Doz-Herkunft'!C14:J14)&"}"} -> {DHBW: 1634; andere Hochschule: 74; Forschungsinstitut: 64; freiberufl./selbst.: ; Öffentliche Einrichtung: ; Rechtsanwalt / StB/ Richter: ; Soz. Einrichtung / Verbände: ; Unternehmen: 326} | Q14: {=_xlfn.LET( _xlpm.keys,Lehrverflechtung!$B$2:$B$31, _xlpm.k,ROW()-1, _xlpm.vals,INDEX(Lehrverflechtung!$C$2:$AF$31,_xlfn.SEQUENCE(30),_xlpm.k), IF(_xlpm.k>30,"","{"&_xlfn.TEXTJOIN("; ",TRUE,_xlpm.keys&": "&_xlpm.vals)&"}") )} -> {Advanced Practice in Healthcare: ; Intensive Care: ; Digitalisierung in der Sozialen Arbeit: ; Governance Sozialer Arbeit: ; Planung und Koordination in der Sozialen Arbeit: ; Soziale Arbeit in der Migrationsgesellschaft: ; Transkulturelle Traumapädagogik: ; Bauingenieurwesen: ; Elektrotechnik und Informationstechnik: 5; Executive Engineering: ; Informatik: 13; Integrated Engineering: 3; Maschinenbau: 294; Wirtschaftsingenieurwesen: 78; Accounting, Controlling, Taxation: ; Data Science and Artificial Intelligence: ; Digital Business Management: ; Entrepreneurship: ; Finance: ; General Business Management: 1; Marketing: ; Master of Business Administration: ; Media and Data-driven Business: ; Personalmanagement und Wirtschaftspsychologie: ; Rechnungswesen Steuern Wirtschaftsrecht: ; Sales and Negotiation: ; Supply Chain Management, Logistics, Production: ; Wirtschaftsinformatik: ; Fachübergreifende Kompetenzen: 51; Wissenschaftliche Weiterbildung: } | R14: {="{"&_xlfn.TEXTJOIN("; ",TRUE,Lehrverflechtung!C$1:AF$1&": "&Lehrverflechtung!C14:AF14)&"}"} -> {Advanced Practice in Healthcare: ; Intensive Care: ; Digitalisierung in der Sozialen Arbeit: ; Governance Sozialer Arbeit: ; Planung und Koordination in der Sozialen Arbeit: ; Soziale Arbeit in der Migrationsgesellschaft: ; Transkulturelle Traumapädagogik: ; Bauingenieurwesen: 2; Elektrotechnik und Informationstechnik: 38; Executive Engineering: 3; Informatik: 1; Integrated Engineering: 86; Maschinenbau: 294; Wirtschaftsingenieurwesen: 132; Accounting, Controlling, Taxation: ; Data Science and Artificial Intelligence: ; Digital Business Management: 1; Entrepreneurship: ; Finance: ; General Business Management: ; Marketing: ; Master of Business Administration: ; Media and Data-driven Business: ; Personalmanagement und Wirtschaftspsychologie: ; Rechnungswesen Steuern Wirtschaftsrecht: ; Sales and Negotiation: ; Supply Chain Management, Logistics, Production: ; Wirtschaftsinformatik: ; Fachübergreifende Kompetenzen: ; Wissenschaftliche Weiterbildung: 34} | S14: 16
A15: Wirtschaftsingenieurwesen | B15: Technik | C15: 56 | D15: 61 | E15: 38 | F15: 43 | G15: 249 | H15: 246 | I15: 210 | J15: 183 | K15: {="{"&_xlfn.TEXTJOIN("; ",TRUE,Vorstudium!C$1:F$1&": "&Vorstudium!C15:F15)&"}"} -> {DHBW: 32; Hochschule: 9; Universität: 2; Ausland/k.A.: } | L15: 0.96142433 | M15: 6.034375 | N15: 2.3217054 | O15: 26.27907 | P15: {="{"&_xlfn.TEXTJOIN("; ",TRUE,'Doz-Herkunft'!C$1:J$1&": "&'Doz-Herkunft'!C15:J15)&"}"} -> {DHBW: 2436; andere Hochschule: 128; Forschungsinstitut: 12; freiberufl./selbst.: 274; Öffentliche Einrichtung: ; Rechtsanwalt / StB/ Richter: ; Soz. Einrichtung / Verbände: ; Unternehmen: 362} | Q15: {=_xlfn.LET( _xlpm.keys,Lehrverflechtung!$B$2:$B$31, _xlpm.k,ROW()-1, _xlpm.vals,INDEX(Lehrverflechtung!$C$2:$AF$31,_xlfn.SEQUENCE(30),_xlpm.k), IF(_xlpm.k>30,"","{"&_xlfn.TEXTJOIN("; ",TRUE,_xlpm.keys&": "&_xlpm.vals)&"}") )} -> {Advanced Practice in Healthcare: ; Intensive Care: ; Digitalisierung in der Sozialen Arbeit: ; Governance Sozialer Arbeit: ; Planung und Koordination in der Sozialen Arbeit: ; Soziale Arbeit in der Migrationsgesellschaft: ; Transkulturelle Traumapädagogik: ; Bauingenieurwesen: 39; Elektrotechnik und Informationstechnik: 19; Executive Engineering: ; Informatik: 28; Integrated Engineering: 29; Maschinenbau: 132; Wirtschaftsingenieurwesen: 421; Accounting, Controlling, Taxation: 16; Data Science and Artificial Intelligence: ; Digital Business Management: 6; Entrepreneurship: ; Finance: ; General Business Management: 8; Marketing: 1; Master of Business Administration: 4; Media and Data-driven Business: 17; Personalmanagement und Wirtschaftspsychologie: 15; Rechnungswesen Steuern Wirtschaftsrecht: ; Sales and Negotiation: 11; Supply Chain Management, Logistics, Production: 15; Wirtschaftsinformatik: 43; Fachübergreifende Kompetenzen: 142; Wissenschaftliche Weiterbildung: } | R15: {="{"&_xlfn.TEXTJOIN("; ",TRUE,Lehrverflechtung!C$1:AF$1&": "&Lehrverflechtung!C15:AF15)&"}"} -> {Advanced Practice in Healthcare: ; Intensive Care: ; Digitalisierung in der Sozialen Arbeit: ; Governance Sozialer Arbeit: ; Planung und Koordination in der Sozialen Arbeit: ; Soziale Arbeit in der Migrationsgesellschaft: ; Transkulturelle Traumapädagogik: ; Bauingenieurwesen: 30; Elektrotechnik und Informationstechnik: 33; Executive Engineering: 21; Informatik: 42; Integrated Engineering: 160; Maschinenbau: 78; Wirtschaftsingenieurwesen: 421; Accounting, Controlling, Taxation: ; Data Science and Artificial Intelligence: 1; Digital Business Management: 4; Entrepreneurship: ; Finance: 4; General Business Management: 12; Marketing: ; Master of Business Administration: ; Media and Data-driven Business: ; Personalmanagement und Wirtschaftspsychologie: 6; Rechnungswesen Steuern Wirtschaftsrecht: ; Sales and Negotiation: ; Supply Chain Management, Logistics, Production: 12; Wirtschaftsinformatik: 5; Fachübergreifende Kompetenzen: ; Wissenschaftliche Weiterbildung: 63} | S15: 18.5
A16: Accounting, Controlling, Taxation | B16: Wirtschaft | C16: 27 | D16: 19 | E16: 22 | F16: 19 | G16: 66 | H16: 74 | I16: 63 | J16: 58 | K16: {="{"&_xlfn.TEXTJOIN("; ",TRUE,Vorstudium!C$1:F$1&": "&Vorstudium!C16:F16)&"}"} -> {DHBW: 10; Hochschule: 8; Universität: 1; Ausland/k.A.: } | L16: 0.85294118 | M16: 4.2413793 | N16: 3.2982456 | O16: 26.631579 | P16: {="{"&_xlfn.TEXTJOIN("; ",TRUE,'Doz-Herkunft'!C$1:J$1&": "&'Doz-Herkunft'!C16:J16)&"}"} -> {DHBW: 1236; andere Hochschule: 32; Forschungsinstitut: ; freiberufl./selbst.: ; Öffentliche Einrichtung: ; Rechtsanwalt / StB/ Richter: 48; Soz. Einrichtung / Verbände: ; Unternehmen: 64} | Q16: {=_xlfn.LET( _xlpm.keys,Lehrverflechtung!$B$2:$B$31, _xlpm.k,ROW()-1, _xlpm.vals,INDEX(Lehrverflechtung!$C$2:$AF$31,_xlfn.SEQUENCE(30),_xlpm.k), IF(_xlpm.k>30,"","{"&_xlfn.TEXTJOIN("; ",TRUE,_xlpm.keys&": "&_xlpm.vals)&"}") )} -> {Advanced Practice in Healthcare: ; Intensive Care: ; Digitalisierung in der Sozialen Arbeit: ; Governance Sozialer Arbeit: ; Planung und Koordination in der Sozialen Arbeit: ; Soziale Arbeit in der Migrationsgesellschaft: ; Transkulturelle Traumapädagogik: ; Bauingenieurwesen: ; Elektrotechnik und Informationstechnik: ; Executive Engineering: ; Informatik: ; Integrated Engineering: ; Maschinenbau: ; Wirtschaftsingenieurwesen: ; Accounting, Controlling, Taxation: 185; Data Science and Artificial Intelligence: ; Digital Business Management: 3; Entrepreneurship: 1; Finance: 23; General Business Management: 32; Marketing: ; Master of Business Administration: ; Media and Data-driven Business: 10; Personalmanagement und Wirtschaftspsychologie: 46; Rechnungswesen Steuern Wirtschaftsrecht: ; Sales and Negotiation: 1; Supply Chain Management, Logistics, Production: 1; Wirtschaftsinformatik: 3; Fachübergreifende Kompetenzen: 68; Wissenschaftliche Weiterbildung: } | R16: {="{"&_xlfn.TEXTJOIN("; ",TRUE,Lehrverflechtung!C$1:AF$1&": "&Lehrverflechtung!C16:AF16)&"}"} -> {Advanced Practice in Healthcare: ; Intensive Care: ; Digitalisierung in der Sozialen Arbeit: ; Governance Sozialer Arbeit: ; Planung und Koordination in der Sozialen Arbeit: ; Soziale Arbeit in der Migrationsgesellschaft: ; Transkulturelle Traumapädagogik: ; Bauingenieurwesen: ; Elektrotechnik und Informationstechnik: ; Executive Engineering: ; Informatik: ; Integrated Engineering: 1; Maschinenbau: ; Wirtschaftsingenieurwesen: 16; Accounting, Controlling, Taxation: 185; Data Science and Artificial Intelligence: ; Digital Business Management: 1; Entrepreneurship: ; Finance: 16; General Business Management: 41; Marketing: ; Master of Business Administration: 3; Media and Data-driven Business: 1; Personalmanagement und Wirtschaftspsychologie: ; Rechnungswesen Steuern Wirtschaftsrecht: ; Sales and Negotiation: ; Supply Chain Management, Logistics, Production: 12; Wirtschaftsinformatik: 2; Fachübergreifende Kompetenzen: ; Wissenschaftliche Weiterbildung: 29} | S16: 14.333333
A17: Data Science and Artificial Intelligence | B17: Wirtschaft | C17: 0 | D17: 0 | E17: 0 | F17: 8 | G17: 0 | H17: 0 | I17: 0 | J17: 8 | K17: {="{"&_xlfn.TEXTJOIN("; ",TRUE,Vorstudium!C$1:F$1&": "&Vorstudium!C17:F17)&"}"} -> {DHBW: 6; Hochschule: 1; Universität: ; Ausland/k.A.: 1} | N17: 3.4270833 | O17: 28.25 | P17: {="{"&_xlfn.TEXTJOIN("; ",TRUE,'Doz-Herkunft'!C$1:J$1&": "&'Doz-Herkunft'!C17:J17)&"}"} -> {DHBW: ; andere Hochschule: ; Forschungsinstitut: ; freiberufl./selbst.: ; Öffentliche Einrichtung: ; Rechtsanwalt / StB/ Richter: ; Soz. Einrichtung / Verbände: ; Unternehmen: } | Q17: {=_xlfn.LET( _xlpm.keys,Lehrverflechtung!$B$2:$B$31, _xlpm.k,ROW()-1, _xlpm.vals,INDEX(Lehrverflechtung!$C$2:$AF$31,_xlfn.SEQUENCE(30),_xlpm.k), IF(_xlpm.k>30,"","{"&_xlfn.TEXTJOIN("; ",TRUE,_xlpm.keys&": "&_xlpm.vals)&"}") )} -> {Advanced Practice in Healthcare: ; Intensive Care: ; Digitalisierung in der Sozialen Arbeit: ; Governance Sozialer Arbeit: ; Planung und Koordination in der Sozialen Arbeit: ; Soziale Arbeit in der Migrationsgesellschaft: ; Transkulturelle Traumapädagogik: ; Bauingenieurwesen: ; Elektrotechnik und Informationstechnik: ; Executive Engineering: ; Informatik: 5; Integrated Engineering: ; Maschinenbau: ; Wirtschaftsingenieurwesen: 1; Accounting, Controlling, Taxation: ; Data Science and Artificial Intelligence: 58; Digital Business Management: 1; Entrepreneurship: ; Finance: 1; General Business Management: ; Marketing: ; Master of Business Administration: ; Media and Data-driven Business: ; Personalmanagement und Wirtschaftspsychologie: ; Rechnungswesen Steuern Wirtschaftsrecht: ; Sales and Negotiation: ; Supply Chain Management, Logistics, Production: ; Wirtschaftsinformatik: 14; Fachübergreifende Kompetenzen: 10; Wissenschaftliche Weiterbildung: } | R17: {="{"&_xlfn.TEXTJOIN("; ",TRUE,Lehrverflechtung!C$1:AF$1&": "&Lehrverflechtung!C17:AF17)&"}"} -> {Advanced Practice in Healthcare: ; Intensive Care: ; Digitalisierung in der Sozialen Arbeit: ; Governance Sozialer Arbeit: ; Planung und Koordination in der Sozialen Arbeit: ; Soziale Arbeit in der Migrationsgesellschaft: ; Transkulturelle Traumapädagogik: ; Bauingenieurwesen: ; Elektrotechnik und Informationstechnik: 1; Executive Engineering: ; Informatik: 11; Integrated Engineering: ; Maschinenbau: ; Wirtschaftsingenieurwesen: ; Accounting, Controlling, Taxation: ; Data Science and Artificial Intelligence: 58; Digital Business Management: ; Entrepreneurship: ; Finance: ; General Business Management: ; Marketing: ; Master of Business Administration: ; Media and Data-driven Business: ; Personalmanagement und Wirtschaftspsychologie: ; Rechnungswesen Steuern Wirtschaftsrecht: ; Sales and Negotiation: ; Supply Chain Management, Logistics, Production: ; Wirtschaftsinformatik: 3; Fachübergreifende Kompetenzen: ; Wissenschaftliche Weiterbildung: 11} | S17: 6
A18: Digital Business Management | B18: Wirtschaft | C18: 27 | D18: 18 | E18: 18 | F18: 9 | G18: 53 | H18: 62 | I18: 60 | J18: 53 | K18: {="{"&_xlfn.TEXTJOIN("; ",TRUE,Vorstudium!C$1:F$1&": "&Vorstudium!C18:F18)&"}"} -> {DHBW: 8; Hochschule: 1; Universität: ; Ausland/k.A.: } | L18: 0.95652174 | M18: 4.75 | N18: 1.7708333 | O18: 24.888889 | P18: {="{"&_xlfn.TEXTJOIN("; ",TRUE,'Doz-Herkunft'!C$1:J$1&": "&'Doz-Herkunft'!C18:J18)&"}"} -> {DHBW: 1225; andere Hochschule: 48; Forschungsinstitut: ; freiberufl./selbst.: ; Öffentliche Einrichtung: ; Rechtsanwalt / StB/ Richter: ; Soz. Einrichtung / Verbände: ; Unternehmen: 16} | Q18: {=_xlfn.LET( _xlpm.keys,Lehrverflechtung!$B$2:$B$31, _xlpm.k,ROW()-1, _xlpm.vals,INDEX(Lehrverflechtung!$C$2:$AF$31,_xlfn.SEQUENCE(30),_xlpm.k), IF(_xlpm.k>30,"","{"&_xlfn.TEXTJOIN("; ",TRUE,_xlpm.keys&": "&_xlpm.vals)&"}") )} -> {Advanced Practice in Healthcare: ; Intensive Care: ; Digitalisierung in der Sozialen Arbeit: ; Governance Sozialer Arbeit: ; Planung und Koordination in der Sozialen Arbeit: ; Soziale Arbeit in der Migrationsgesellschaft: ; Transkulturelle Traumapädagogik: ; Bauingenieurwesen: ; Elektrotechnik und Informationstechnik: ; Executive Engineering: ; Informatik: 2; Integrated Engineering: ; Maschinenbau: 1; Wirtschaftsingenieurwesen: 4; Accounting, Controlling, Taxation: 1; Data Science and Artificial Intelligence: ; Digital Business Management: 111; Entrepreneurship: 1; Finance: ; General Business Management: 17; Marketing: 4; Master of Business Administration: ; Media and Data-driven Business: 1; Personalmanagement und Wirtschaftspsychologie: 4; Rechnungswesen Steuern Wirtschaftsrecht: ; Sales and Negotiation: 2; Supply Chain Management, Logistics, Production: ; Wirtschaftsinformatik: 23; Fachübergreifende Kompetenzen: 43; Wissenschaftliche Weiterbildung: } | R18: {="{"&_xlfn.TEXTJOIN("; ",TRUE,Lehrverflechtung!C$1:AF$1&": "&Lehrverflechtung!C18:AF18)&"}"} -> {Advanced Practice in Healthcare: ; Intensive Care: ; Digitalisierung in der Sozialen Arbeit: 1; Governance Sozialer Arbeit: ; Planung und Koordination in der Sozialen Arbeit: ; Soziale Arbeit in der Migrationsgesellschaft: ; Transkulturelle Traumapädagogik: ; Bauingenieurwesen: ; Elektrotechnik und Informationstechnik: ; Executive Engineering: ; Informatik: ; Integrated Engineering: 7; Maschinenbau: ; Wirtschaftsingenieurwesen: 6; Accounting, Controlling, Taxation: 3; Data Science and Artificial Intelligence: 1; Digital Business Management: 111; Entrepreneurship: ; Finance: 1; General Business Management: 35; Marketing: 10; Master of Business Administration: 5; Media and Data-driven Business: 4; Personalmanagement und Wirtschaftspsychologie: ; Rechnungswesen Steuern Wirtschaftsrecht: ; Sales and Negotiation: 7; Supply Chain Management, Logistics, Production: 8; Wirtschaftsinformatik: 50; Fachübergreifende Kompetenzen: ; Wissenschaftliche Weiterbildung: 8} | S18: 10.428571
A19: Entrepreneurship | B19: Wirtschaft | C19: 11 | D19: 3 | E19: 5 | F19: 5 | G19: 11 | H19: 13 | I19: 17 | J19: 17 | K19: {="{"&_xlfn.TEXTJOIN("; ",TRUE,Vorstudium!C$1:F$1&": "&Vorstudium!C19:F19)&"}"} -> {DHBW: 4; Hochschule: 1; Universität: ; Ausland/k.A.: } | L19: 0.57142857 | M19: 4.25 | N19: 1.15 | O19: 27.6 | P19: {="{"&_xlfn.TEXTJOIN("; ",TRUE,'Doz-Herkunft'!C$1:J$1&": "&'Doz-Herkunft'!C19:J19)&"}"} -> {DHBW: 488; andere Hochschule: ; Forschungsinstitut: ; freiberufl./selbst.: 20; Öffentliche Einrichtung: ; Rechtsanwalt / StB/ Richter: ; Soz. Einrichtung / Verbände: ; Unternehmen: } | Q19: {=_xlfn.LET( _xlpm.keys,Lehrverflechtung!$B$2:$B$31, _xlpm.k,ROW()-1, _xlpm.vals,INDEX(Lehrverflechtung!$C$2:$AF$31,_xlfn.SEQUENCE(30),_xlpm.k), IF(_xlpm.k>30,"","{"&_xlfn.TEXTJOIN("; ",TRUE,_xlpm.keys&": "&_xlpm.vals)&"}") )} -> {Advanced Practice in Healthcare: ; Intensive Care: ; Digitalisierung in der Sozialen Arbeit: ; Governance Sozialer Arbeit: ; Planung und Koordination in der Sozialen Arbeit: ; Soziale Arbeit in der Migrationsgesellschaft: ; Transkulturelle Traumapädagogik: ; Bauingenieurwesen: ; Elektrotechnik und Informationstechnik: ; Executive Engineering: ; Informatik: ; Integrated Engineering: ; Maschinenbau: ; Wirtschaftsingenieurwesen: ; Accounting, Controlling, Taxation: ; Data Science and Artificial Intelligence: ; Digital Business Management: ; Entrepreneurship: 45; Finance: ; General Business Management: 5; Marketing: 3; Master of Business Administration: ; Media and Data-driven Business: 1; Personalmanagement und Wirtschaftspsychologie: ; Rechnungswesen Steuern Wirtschaftsrecht: ; Sales and Negotiation: ; Supply Chain Management, Logistics, Production: ; Wirtschaftsinformatik: ; Fachübergreifende Kompetenzen: 14; Wissenschaftliche Weiterbildung: } | R19: {="{"&_xlfn.TEXTJOIN("; ",TRUE,Lehrverflechtung!C$1:AF$1&": "&Lehrverflechtung!C19:AF19)&"}"} -> {Advanced Practice in Healthcare: ; Intensive Care: ; Digitalisierung in der Sozialen Arbeit: ; Governance Sozialer Arbeit: ; Planung und Koordination in der Sozialen Arbeit: ; Soziale Arbeit in der Migrationsgesellschaft: ; Transkulturelle Traumapädagogik: ; Bauingenieurwesen: ; Elektrotechnik und Informationstechnik: ; Executive Engineering: 3; Informatik: ; Integrated Engineering: ; Maschinenbau: ; Wirtschaftsingenieurwesen: ; Accounting, Controlling, Taxation: 1; Data Science and Artificial Intelligence: ; Digital Business Management: 1; Entrepreneurship: 45; Finance: 1; General Business Management: 46; Marketing: ; Master of Business Administration: 1; Media and Data-driven Business: ; Personalmanagement und Wirtschaftspsychologie: ; Rechnungswesen Steuern Wirtschaftsrecht: ; Sales and Negotiation: 3; Supply Chain Management, Logistics, Production: ; Wirtschaftsinformatik: ; Fachübergreifende Kompetenzen: ; Wissenschaftliche Weiterbildung: 22} | S19: 11.666667
A20: Finance | B20: Wirtschaft | C20: 16 | D20: 16 | E20: 16 | F20: 14 | G20: 38 | H20: 47 | I20: 42 | J20: 39 | K20: {="{"&_xlfn.TEXTJOIN("; ",TRUE,Vorstudium!C$1:F$1&": "&Vorstudium!C20:F20)&"}"} -> {DHBW: 12; Hochschule: 2; Universität: ; Ausland/k.A.: } | L20: 0.97777778 | M20: 3.9318182 | N20: 1.4358974 | O20: 25.071429 | P20: {="{"&_xlfn.TEXTJOIN("; ",TRUE,'Doz-Herkunft'!C$1:J$1&": "&'Doz-Herkunft'!C20:J20)&"}"} -> {DHBW: 728; andere Hochschule: 72; Forschungsinstitut: ; freiberufl./selbst.: ; Öffentliche Einrichtung: ; Rechtsanwalt / StB/ Richter: 16; Soz. Einrichtung / Verbände: ; Unternehmen: 136} | Q20: {=_xlfn.LET( _xlpm.keys,Lehrverflechtung!$B$2:$B$31, _xlpm.k,ROW()-1, _xlpm.vals,INDEX(Lehrverflechtung!$C$2:$AF$31,_xlfn.SEQUENCE(30),_xlpm.k), IF(_xlpm.k>30,"","{"&_xlfn.TEXTJOIN("; ",TRUE,_xlpm.keys&": "&_xlpm.vals)&"}") )} -> {Advanced Practice in Healthcare: ; Intensive Care: ; Digitalisierung in der Sozialen Arbeit: ; Governance Sozialer Arbeit: ; Planung und Koordination in der Sozialen Arbeit: ; Soziale Arbeit in der Migrationsgesellschaft: ; Transkulturelle Traumapädagogik: ; Bauingenieurwesen: ; Elektrotechnik und Informationstechnik: 1; Executive Engineering: ; Informatik: ; Integrated Engineering: ; Maschinenbau: ; Wirtschaftsingenieurwesen: 4; Accounting, Controlling, Taxation: 16; Data Science and Artificial Intelligence: ; Digital Business Management: 1; Entrepreneurship: 1; Finance: 103; General Business Management: 45; Marketing: ; Master of Business Administration: ; Media and Data-driven Business: 1; Personalmanagement und Wirtschaftspsychologie: 3; Rechnungswesen Steuern Wirtschaftsrecht: ; Sales and Negotiation: ; Supply Chain Management, Logistics, Production: ; Wirtschaftsinformatik: ; Fachübergreifende Kompetenzen: 42; Wissenschaftliche Weiterbildung: } | R20: {="{"&_xlfn.TEXTJOIN("; ",TRUE,Lehrverflechtung!C$1:AF$1&": "&Lehrverflechtung!C20:AF20)&"}"} -> {Advanced Practice in Healthcare: ; Intensive Care: ; Digitalisierung in der Sozialen Arbeit: ; Governance Sozialer Arbeit: ; Planung und Koordination in der Sozialen Arbeit: ; Soziale Arbeit in der Migrationsgesellschaft: ; Transkulturelle Traumapädagogik: ; Bauingenieurwesen: ; Elektrotechnik und Informationstechnik: ; Executive Engineering: ; Informatik: ; Integrated Engineering: ; Maschinenbau: ; Wirtschaftsingenieurwesen: ; Accounting, Controlling, Taxation: 23; Data Science and Artificial Intelligence: 1; Digital Business Management: ; Entrepreneurship: ; Finance: 103; General Business Management: 12; Marketing: ; Master of Business Administration: ; Media and Data-driven Business: ; Personalmanagement und Wirtschaftspsychologie: ; Rechnungswesen Steuern Wirtschaftsrecht: ; Sales and Negotiation: ; Supply Chain Management, Logistics, Production: ; Wirtschaftsinformatik: ; Fachübergreifende Kompetenzen: ; Wissenschaftliche Weiterbildung: 11} | S20: 11.25
A21: General Business Management | B21: Wirtschaft | C21: 40 | D21: 42 | E21: 31 | F21: 45 | G21: 94 | H21: 120 | I21: 94 | J21: 101 | K21: {="{"&_xlfn.TEXTJOIN("; ",TRUE,Vorstudium!C$1:F$1&": "&Vorstudium!C21:F21)&"}"} -> {DHBW: 39; Hochschule: 4; Universität: 1; Ausland/k.A.: 1} | L21: 0.95535714 | M21: 3.8691589 | N21: 2.1856061 | O21: 25.488889 | P21: {="{"&_xlfn.TEXTJOIN("; ",TRUE,'Doz-Herkunft'!C$1:J$1&": "&'Doz-Herkunft'!C21:J21)&"}"} -> {DHBW: 1194; andere Hochschule: 16; Forschungsinstitut: ; freiberufl./selbst.: ; Öffentliche Einrichtung: ; Rechtsanwalt / StB/ Richter: ; Soz. Einrichtung / Verbände: ; Unternehmen: 112} | Q21: {=_xlfn.LET( _xlpm.keys,Lehrverflechtung!$B$2:$B$31, _xlpm.k,ROW()-1, _xlpm.vals,INDEX(Lehrverflechtung!$C$2:$AF$31,_xlfn.SEQUENCE(30),_xlpm.k), IF(_xlpm.k>30,"","{"&_xlfn.TEXTJOIN("; ",TRUE,_xlpm.keys&": "&_xlpm.vals)&"}") )} -> {Advanced Practice in Healthcare: ; Intensive Care: ; Digitalisierung in der Sozialen Arbeit: ; Governance Sozialer Arbeit: ; Planung und Koordination in der Sozialen Arbeit: ; Soziale Arbeit in der Migrationsgesellschaft: ; Transkulturelle Traumapädagogik: ; Bauingenieurwesen: ; Elektrotechnik und Informationstechnik: 1; Executive Engineering: ; Informatik: ; Integrated Engineering: 1; Maschinenbau: ; Wirtschaftsingenieurwesen: 12; Accounting, Controlling, Taxation: 41; Data Science and Artificial Intelligence: ; Digital Business Management: 35; Entrepreneurship: 46; Finance: 12; General Business Management: 230; Marketing: 20; Master of Business Administration: 1; Media and Data-driven Business: 14; Personalmanagement und Wirtschaftspsychologie: 86; Rechnungswesen Steuern Wirtschaftsrecht: ; Sales and Negotiation: 47; Supply Chain Management, Logistics, Production: 7; Wirtschaftsinformatik: 22; Fachübergreifende Kompetenzen: 133; Wissenschaftliche Weiterbildung: } | R21: {="{"&_xlfn.TEXTJOIN("; ",TRUE,Lehrverflechtung!C$1:AF$1&": "&Lehrverflechtung!C21:AF21)&"}"} -> {Advanced Practice in Healthcare: ; Intensive Care: ; Digitalisierung in der Sozialen Arbeit: ; Governance Sozialer Arbeit: ; Planung und Koordination in der Sozialen Arbeit: ; Soziale Arbeit in der Migrationsgesellschaft: ; Transkulturelle Traumapädagogik: ; Bauingenieurwesen: 1; Elektrotechnik und Informationstechnik: ; Executive Engineering: ; Informatik: ; Integrated Engineering: 3; Maschinenbau: 1; Wirtschaftsingenieurwesen: 8; Accounting, Controlling, Taxation: 32; Data Science and Artificial Intelligence: ; Digital Business Management: 17; Entrepreneurship: 5; Finance: 45; General Business Management: 230; Marketing: 11; Master of Business Administration: 12; Media and Data-driven Business: 1; Personalmanagement und Wirtschaftspsychologie: 8; Rechnungswesen Steuern Wirtschaftsrecht: ; Sales and Negotiation: 28; Supply Chain Management, Logistics, Production: 17; Wirtschaftsinformatik: 13; Fachübergreifende Kompetenzen: ; Wissenschaftliche Weiterbildung: 29} | S21: 22
